Traceback (most recent call last):
  File "/opt/anaconda3/lib/python3.8/site-packages/jupyter_cache/executors/utils.py", line 58, in single_nb_execution
    executenb(
  File "/opt/anaconda3/lib/python3.8/site-packages/nbclient/client.py", line 1112, in execute
    return NotebookClient(nb=nb, resources=resources, km=km, **kwargs).execute()
  File "/opt/anaconda3/lib/python3.8/site-packages/nbclient/util.py", line 74, in wrapped
    return just_run(coro(*args, **kwargs))
  File "/opt/anaconda3/lib/python3.8/site-packages/nbclient/util.py", line 53, in just_run
    return loop.run_until_complete(coro)
  File "/opt/anaconda3/lib/python3.8/asyncio/base_events.py", line 616, in run_until_complete
    return future.result()
  File "/opt/anaconda3/lib/python3.8/site-packages/nbclient/client.py", line 553, in async_execute
    await self.async_execute_cell(
  File "/opt/anaconda3/lib/python3.8/site-packages/nbclient/client.py", line 857, in async_execute_cell
    self._check_raise_for_error(cell, exec_reply)
  File "/opt/anaconda3/lib/python3.8/site-packages/nbclient/client.py", line 760, in _check_raise_for_error
    raise CellExecutionError.from_cell_and_msg(cell, exec_reply_content)
nbclient.exceptions.CellExecutionError: An error occurred while executing the following cell:
------------------
df['res0'] = mdl.resid
df['res1'] = df['res0']
df['res1'][1].dell()
df['res2'] = df['res1']
df['res2'][2] = 0
df['res3'] = df['res2']
df['res3'][3] = 0
df.dropna()

------------------

[0;31m---------------------------------------------------------------------------[0m
[0;31mAttributeError[0m                            Traceback (most recent call last)
Cell [0;32mIn[11], line 3[0m
[1;32m      1[0m df[[38;5;124m'[39m[38;5;124mres0[39m[38;5;124m'[39m] [38;5;241m=[39m mdl[38;5;241m.[39mresid
[1;32m      2[0m df[[38;5;124m'[39m[38;5;124mres1[39m[38;5;124m'[39m] [38;5;241m=[39m df[[38;5;124m'[39m[38;5;124mres0[39m[38;5;124m'[39m]
[0;32m----> 3[0m [43mdf[49m[43m[[49m[38;5;124;43m'[39;49m[38;5;124;43mres1[39;49m[38;5;124;43m'[39;49m[43m][49m[43m[[49m[38;5;241;43m1[39;49m[43m][49m[38;5;241;43m.[39;49m[43mdell[49m()
[1;32m      4[0m df[[38;5;124m'[39m[38;5;124mres2[39m[38;5;124m'[39m] [38;5;241m=[39m df[[38;5;124m'[39m[38;5;124mres1[39m[38;5;124m'[39m]
[1;32m      5[0m df[[38;5;124m'[39m[38;5;124mres2[39m[38;5;124m'[39m][[38;5;241m2[39m] [38;5;241m=[39m [38;5;241m0[39m

[0;31mAttributeError[0m: 'numpy.float64' object has no attribute 'dell'
AttributeError: 'numpy.float64' object has no attribute 'dell'

